Workbook

Sheet ⚙️ Assumptions
A1: Economy Simulation: Master Assumptions
A2: 🔵 Assumptions from data
A4: PLAYER PROGRESSION
A5: Parameter | B5: Value | C5: Notes
A6: Avg levels per session | B6: 2 | C6: How many levels played per session
A7: Sessions per day (avg player) | B7: 2 | C7: Daily active sessions
A8: Daily level clears (avg) | B8: =B6*B7 -> 4 | C8: Auto-calculated
A9: Level difficulty: % completed first try | B9: 0.6 | C9: Win rate on first attempt
A10: In-level boosters/revive purchase rate | B10: 0.1 | C10: % of near-fail sessions buying boosters
A11: Level difficulty: bonus coin | B11: 1.5 | C11: Bonus from Hard/Super Difficulties
A12: coin (SOFT CURRENCY) ECONOMY
A13: Parameter | B13: Value | C13: Notes
A14: coin per level clear (base) | B14: 20 | C14: coin earned for completing a level
A15: coin earned per social action | B15: 0 | C15: coin rewarded for completing a social interaction (e.g. helping another player)
A16: Daily coin from levels | B16: =B8*B14*B11 -> 120 | C16: Base level clears only (before video)
A17: Total daily coin income | B17: =B27+B26+'🎪 Live-ops Calendar'!J13 -> 356.95 | C17: Base level clears + video bonus + live-ops daily avg
A18: Daily coin lost to in-level purchases | B18: =B38 -> 92 | C18: Auto-calculated from Revives/boosters
A19: Net daily coin income | B19: =B17-B18 -> 264.95 | C19: Gross income minus coin drain
A21: REWARDED VIDEO — coin MULTIPLIER
A22: Parameter | B22: Value | C22: Notes
A23: Reward video multiplier | B23: 3 | C23: 100% of base — watching doubles the coin earned per clear
A24: Video watch rate | B24: 0.25 | C24: 50% of level clears are followed by a watched video
A25: Effective video bonus per clear | B25: =B14*B23*B24*B11 -> 22.5 | C25: Base coin × multiplier × watch rate x bonus from difficulties
A26: Daily coin from rewarded video | B26: =B8*B25 -> 90 | C26: Daily clears × effective video bonus
A27: Daily coin from levels (base) | B27: =B8*B14*B11 -> 120 | C27: Base level clears, no video
A29: Revive/Boosters — coin SINK
A30: Parameter | B30: Value | C30: Notes
A31: Revive/Boosters cost (coin) | B31: =AVERAGE(120,160,240,400) -> 230 | C31: Average cost of all boosters and revive
A32: % failed levels triggering | B32: 1 | C32: Est. share of failed levels
A33: Purchase rate (of triggers) | B33: 0.1 | C33: Linked to purchase rate assumption
A34: Daily levels played | B34: =B8 -> 4 | C34: Pulled from Player Progression
A35: Daily failed levels | B35: =B34*(1-B9) -> 1.6 | C35: Daily levels played × (1 - win rate)
A36: Daily triggers | B36: =B8 -> 4 | C36: Failed levels × Trigger rate
A37: Daily purchases | B37: =B36*B33 -> 0.4 | C37: Triggers × purchase rate
A38: Daily coin lost to levels | B38: =B37*B31 -> 92 | C38: Net coin drained per day — sink
A39: LIVE-OPS EVENTS
A40: Event | B40: Cadence (days) | C40: Max coin Reward
A41: Live-ops Event 1 (Key Collection) | B41: 4 | C41: 1400
A42: Live-ops Event 2 (Master Pass) | B42: 30 | C42: 480
A43: Live-ops Event 3 (Win Streak) | B43: 3 | C43: 420
...

Sheet 📈 Player Journey
A1: Player Journey Simulation (per player, cumulative)
A2: Cumulative gold from all sources vs level sink. All values pull from ⚙️ Assumptions & 🎪 Live-ops. Does not calculate the first free 600 coins
A3: Level | B3: Days Active | C3: Level Clears Gold (cum) | D3: Video Bonus Gold (cum) | E3: Live-ops Gold (cum) | F3: Coins Spent (cum) | G3: Net Gold Balance
A4: 1 | B4: =ROUND(1/'⚙️ Assumptions'!B8,1) -> 0.3 | C4: 20 | D4: =ROUND(1*'⚙️ Assumptions'!B25,0) -> 23 | E4: =ROUND((1/'⚙️ Assumptions'!B8)*'🎪 Live-ops Calendar'!J13,0) -> 37 | F4: =ROUND((1/'⚙️ Assumptions'!B8)*'⚙️ Assumptions'!B38,0) -> 23 | G4: =C4+D4+E4-F4 -> 57
A5: 2 | B5: =ROUND(2/'⚙️ Assumptions'!B8,1) -> 0.5 | C5: 40 | D5: =ROUND(2*'⚙️ Assumptions'!B25,0) -> 45 | E5: =ROUND((2/'⚙️ Assumptions'!B8)*'🎪 Live-ops Calendar'!J13,0) -> 73 | F5: =ROUND((2/'⚙️ Assumptions'!B8)*'⚙️ Assumptions'!B38,0) -> 46 | G5: =C5+D5+E5-F5 -> 112
A6: 3 | B6: =ROUND(3/'⚙️ Assumptions'!B8,1) -> 0.8 | C6: 60 | D6: =ROUND(3*'⚙️ Assumptions'!B25,0) -> 68 | E6: =ROUND((3/'⚙️ Assumptions'!B8)*'🎪 Live-ops Calendar'!J13,0) -> 110 | F6: =ROUND((3/'⚙️ Assumptions'!B8)*'⚙️ Assumptions'!B38,0) -> 69 | G6: =C6+D6+E6-F6 -> 169
A7: 4 | B7: =ROUND(4/'⚙️ Assumptions'!B8,1) -> 1 | C7: 100 | D7: =ROUND(4*'⚙️ Assumptions'!B25,0) -> 90 | E7: =ROUND((4/'⚙️ Assumptions'!B8)*'🎪 Live-ops Calendar'!J13,0) -> 147 | F7: =ROUND((4/'⚙️ Assumptions'!B8)*'⚙️ Assumptions'!B38,0) -> 92 | G7: =C7+D7+E7-F7 -> 245
A8: 5 | B8: =ROUND(5/'⚙️ Assumptions'!B8,1) -> 1.3 | C8: =5*'⚙️ Assumptions'!B14*'⚙️ Assumptions'!B11 -> 150 | D8: =ROUND(5*'⚙️ Assumptions'!B25,0) -> 113 | E8: =ROUND((5/'⚙️ Assumptions'!B8)*'🎪 Live-ops Calendar'!J13,0) -> 184 | F8: =ROUND((5/'⚙️ Assumptions'!B8)*'⚙️ Assumptions'!B38,0) -> 115 | G8: =C8+D8+E8-F8 -> 332
A9: 8 | B9: =ROUND(8/'⚙️ Assumptions'!B8,1) -> 2 | C9: =8*'⚙️ Assumptions'!B14*'⚙️ Assumptions'!B11 -> 240 | D9: =ROUND(8*'⚙️ Assumptions'!B25,0) -> 180 | E9: =ROUND((8/'⚙️ Assumptions'!B8)*'🎪 Live-ops Calendar'!J13,0) -> 294 | F9: =ROUND((8/'⚙️ Assumptions'!B8)*'⚙️ Assumptions'!B38,0) -> 184 | G9: =C9+D9+E9-F9 -> 530
A10: 10 | B10: =ROUND(10/'⚙️ Assumptions'!B8,1) -> 2.5 | C10: =10*'⚙️ Assumptions'!B14*'⚙️ Assumptions'!B11 -> 300 | D10: =ROUND(10*'⚙️ Assumptions'!B25,0) -> 225 | E10: =ROUND((10/'⚙️ Assumptions'!B8)*'🎪 Live-ops Calendar'!J13,0) -> 367 | F10: =ROUND((10/'⚙️ Assumptions'!B8)*'⚙️ Assumptions'!B38,0) -> 230 | G10: =C10+D10+E10-F10 -> 662
A11: 15 | B11: =ROUND(15/'⚙️ Assumptions'!B8,1) -> 3.8 | C11: =15*'⚙️ Assumptions'!B14*'⚙️ Assumptions'!B11 -> 450 | D11: =ROUND(15*'⚙️ Assumptions'!B25,0) -> 338 | E11: =ROUND((15/'⚙️ Assumptions'!B8)*'🎪 Live-ops Calendar'!J13,0) -> 551 | F11: =ROUND((15/'⚙️ Assumptions'!B8)*'⚙️ Assumptions'!B38,0) -> 345 | G11: =C11+D11+E11-F11 -> 994
A12: 20 | B12: =ROUND(20/'⚙️ Assumptions'!B8,1) -> 5 | C12: =20*'⚙️ Assumptions'!B14*'⚙️ Assumptions'!B11 -> 600 | D12: =ROUND(20*'⚙️ Assumptions'!B25,0) -> 450 | E12: =ROUND((20/'⚙️ Assumptions'!B8)*'🎪 Live-ops Calendar'!J13,0) -> 735 | F12: =ROUND((20/'⚙️ Assumptions'!B8)*'⚙️ Assumptions'!B38,0) -> 460 | G12: =C12+D12+E12-F12 -> 1325
A13: 25 | B13: =ROUND(25/'⚙️ Assumptions'!B8,1) -> 6.3 | C13: =25*'⚙️ Assumptions'!B14*'⚙️ Assumptions'!B11 -> 750 | D13: =ROUND(25*'⚙️ Assumptions'!B25,0) -> 563 | E13: =ROUND((25/'⚙️ Assumptions'!B8)*'🎪 Live-ops Calendar'!J13,0) -> 918 | F13: =ROUND((25/'⚙️ Assumptions'!B8)*'⚙️ Assumptions'!B38,0) -> 575 | G13: =C13+D13+E13-F13 -> 1656
A14: 30 | B14: =ROUND(30/'⚙️ Assumptions'!B8,1) -> 7.5 | C14: =30*'⚙️ Assumptions'!B14*'⚙️ Assumptions'!B11 -> 900 | D14: =ROUND(30*'⚙️ Assumptions'!B25,0) -> 675 | E14: =ROUND((30/'⚙️ Assumptions'!B8)*'🎪 Live-ops Calendar'!J13,0) -> 1102 | F14: =ROUND((30/'⚙️ Assumptions'!B8)*'⚙️ Assumptions'!B38,0) -> 690 | G14: =C14+D14+E14-F14 -> 1987
A15: 40 | B15: =ROUND(40/'⚙️ Assumptions'!B8,1) -> 10 | C15: =40*'⚙️ Assumptions'!B14*'⚙️ Assumptions'!B11 -> 1200 | D15: =ROUND(40*'⚙️ Assumptions'!B25,0) -> 900 | E15: =ROUND((40/'⚙️ Assumptions'!B8)*'🎪 Live-ops Calendar'!J13,0) -> 1470 | F15: =ROUND((40/'⚙️ Assumptions'!B8)*'⚙️ Assumptions'!B38,0) -> 920 | G15: =C15+D15+E15-F15 -> 2650
A16: 50 | B16: =ROUND(50/'⚙️ Assumptions'!B8,1) -> 12.5 | C16: =50*'⚙️ Assumptions'!B14*'⚙️ Assumptions'!B11 -> 1500 | D16: =ROUND(50*'⚙️ Assumptions'!B25,0) -> 1125 | E16: =ROUND((50/'⚙️ Assumptions'!B8)*'🎪 Live-ops Calendar'!J13,0) -> 1837 | F16: =ROUND((50/'⚙️ Assumptions'!B8)*'⚙️ Assumptions'!B38,0) -> 1150 | G16: =C16+D16+E16-F16 -> 3312
A17: 60 | B17: =ROUND(60/'⚙️ Assumptions'!B8,1) -> 15 | C17: =60*'⚙️ Assumptions'!B14*'⚙️ Assumptions'!B11 -> 1800 | D17: =ROUND(60*'⚙️ Assumptions'!B25,0) -> 1350 | E17: =ROUND((60/'⚙️ Assumptions'!B8)*'🎪 Live-ops Calendar'!J13,0) -> 2204 | F17: =ROUND((60/'⚙️ Assumptions'!B8)*'⚙️ Assumptions'!B38,0) -> 1380 | G17: =C17+D17+E17-F17 -> 3974
A18: 75 | B18: =ROUND(75/'⚙️ Assumptions'!B8,1) -> 18.8 | C18: =75*'⚙️ Assumptions'!B14*'⚙️ Assumptions'!B11 -> 2250 | D18: =ROUND(75*'⚙️ Assumptions'!B25,0) -> 1688 | E18: =ROUND((75/'⚙️ Assumptions'!B8)*'🎪 Live-ops Calendar'!J13,0) -> 2755 | F18: =ROUND((75/'⚙️ Assumptions'!B8)*'⚙️ Assumptions'!B38,0) -> 1725 | G18: =C18+D18+E18-F18 -> 4968
A19: 100 | B19: =ROUND(100/'⚙️ Assumptions'!B8,1) -> 25 | C19: =100*'⚙️ Assumptions'!B14*'⚙️ Assumptions'!B11 -> 3000 | D19: =ROUND(100*'⚙️ Assumptions'!B25,0) -> 2250 | E19: =ROUND((100/'⚙️ Assumptions'!B8)*'🎪 Live-ops Calendar'!J13,0) -> 3674 | F19: =ROUND((100/'⚙️ Assumptions'!B8)*'⚙️ Assumptions'!B38,0) -> 2300 | G19: =C19+D19+E19-F19 -> 6624
A20: 125 | B20: =ROUND(125/'⚙️ Assumptions'!B8,1) -> 31.3 | C20: =125*'⚙️ Assumptions'!B14*'⚙️ Assumptions'!B11 -> 3750 | D20: =ROUND(125*'⚙️ Assumptions'!B25,0) -> 2813 | E20: =ROUND((125/'⚙️ Assumptions'!B8)*'🎪 Live-ops Calendar'!J13,0) -> 4592 | F20: =ROUND((125/'⚙️ Assumptions'!B8)*'⚙️ Assumptions'!B38,0) -> 2875 | G20: =C20+D20+E20-F20 -> 8280
A21: 150 | B21: =ROUND(150/'⚙️ Assumptions'!B8,1) -> 37.5 | C21: =150*'⚙️ Assumptions'!B14*'⚙️ Assumptions'!B11 -> 4500 | D21: =ROUND(150*'⚙️ Assumptions'!B25,0) -> 3375 | E21: =ROUND((150/'⚙️ Assumptions'!B8)*'🎪 Live-ops Calendar'!J13,0) -> 5511 | F21: =ROUND((150/'⚙️ Assumptions'!B8)*'⚙️ Assumptions'!B38,0) -> 3450 | G21: =C21+D21+E21-F21 -> 9936
A22: 175 | B22: =ROUND(175/'⚙️ Assumptions'!B8,1) -> 43.8 | C22: =175*'⚙️ Assumptions'!B14*'⚙️ Assumptions'!B11 -> 5250 | D22: =ROUND(175*'⚙️ Assumptions'!B25,0) -> 3938 | E22: =ROUND((175/'⚙️ Assumptions'!B8)*'🎪 Live-ops Calendar'!J13,0) -> 6429 | F22: =ROUND((175/'⚙️ Assumptions'!B8)*'⚙️ Assumptions'!B38,0) -> 4025 | G22: =C22+D22+E22-F22 -> 11592
A23: 200 | B23: =ROUND(200/'⚙️ Assumptions'!B8,1) -> 50 | C23: =200*'⚙️ Assumptions'!B14*'⚙️ Assumptions'!B11 -> 6000 | D23: =ROUND(200*'⚙️ Assumptions'!B25,0) -> 4500 | E23: =ROUND((200/'⚙️ Assumptions'!B8)*'🎪 Live-ops Calendar'!J13,0) -> 7348 | F23: =ROUND((200/'⚙️ Assumptions'!B8)*'⚙️ Assumptions'!B38,0) -> 4600 | G23: =C23+D23+E23-F23 -> 13248
A24: 225 | B24: =ROUND(225/'⚙️ Assumptions'!B8,1) -> 56.3 | C24: =225*'⚙️ Assumptions'!B14*'⚙️ Assumptions'!B11 -> 6750 | D24: =ROUND(225*'⚙️ Assumptions'!B25,0) -> 5063 | E24: =ROUND((225/'⚙️ Assumptions'!B8)*'🎪 Live-ops Calendar'!J13,0) -> 8266 | F24: =ROUND((225/'⚙️ Assumptions'!B8)*'⚙️ Assumptions'!B38,0) -> 5175 | G24: =C24+D24+E24-F24 -> 14904
A25: 250 | B25: =ROUND(250/'⚙️ Assumptions'!B8,1) -> 62.5 | C25: =A25*'⚙️ Assumptions'!$B$14*'⚙️ Assumptions'!$B$11 -> 7500 | D25: =ROUND(250*'⚙️ Assumptions'!B25,0) -> 5625 | E25: =ROUND((250/'⚙️ Assumptions'!B8)*'🎪 Live-ops Calendar'!J13,0) -> 9184 | F25: =ROUND((250/'⚙️ Assumptions'!B8)*'⚙️ Assumptions'!B38,0) -> 5750 | G25: =C25+D25+E25-F25 -> 16559
A26: 275 | B26: =ROUND(275/'⚙️ Assumptions'!B8,1) -> 68.8 | C26: =A26*'⚙️ Assumptions'!$B$14*'⚙️ Assumptions'!$B$11 -> 8250 | D26: =ROUND(275*'⚙️ Assumptions'!B25,0) -> 6188 | E26: =ROUND((275/'⚙️ Assumptions'!B8)*'🎪 Live-ops Calendar'!J13,0) -> 10103 | F26: =ROUND((275/'⚙️ Assumptions'!B8)*'⚙️ Assumptions'!B38,0) -> 6325 | G26: =C26+D26+E26-F26 -> 18216
A27: 300 | B27: =ROUND(300/'⚙️ Assumptions'!B8,1) -> 75 | C27: =A27*'⚙️ Assumptions'!$B$14*'⚙️ Assumptions'!$B$11 -> 9000 | D27: =ROUND(300*'⚙️ Assumptions'!B25,0) -> 6750 | E27: =ROUND((300/'⚙️ Assumptions'!B8)*'🎪 Live-ops Calendar'!J13,0) -> 11021 | F27: =ROUND((300/'⚙️ Assumptions'!B8)*'⚙️ Assumptions'!B38,0) -> 6900 | G27: =C27+D27+E27-F27 -> 19871
A28: 325 | B28: =ROUND(325/'⚙️ Assumptions'!B8,1) -> 81.3 | C28: =A28*'⚙️ Assumptions'!$B$14*'⚙️ Assumptions'!$B$11 -> 9750 | D28: =ROUND(325*'⚙️ Assumptions'!B25,0) -> 7313 | E28: =ROUND((325/'⚙️ Assumptions'!B8)*'🎪 Live-ops Calendar'!J13,0) -> 11940 | F28: =ROUND((325/'⚙️ Assumptions'!B8)*'⚙️ Assumptions'!B38,0) -> 7475 | G28: =C28+D28+E28-F28 -> 21528
A29: 350 | B29: =ROUND(350/'⚙️ Assumptions'!B8,1) -> 87.5 | C29: =A29*'⚙️ Assumptions'!$B$14*'⚙️ Assumptions'!$B$11 -> 10500 | D29: =ROUND(350*'⚙️ Assumptions'!B25,0) -> 7875 | E29: =ROUND((350/'⚙️ Assumptions'!B8)*'🎪 Live-ops Calendar'!J13,0) -> 12858 | F29: =ROUND((350/'⚙️ Assumptions'!B8)*'⚙️ Assumptions'!B38,0) -> 8050 | G29: =C29+D29+E29-F29 -> 23183
A30: 375 | B30: =ROUND(375/'⚙️ Assumptions'!B8,1) -> 93.8 | C30: =A30*'⚙️ Assumptions'!$B$14*'⚙️ Assumptions'!$B$11 -> 11250 | D30: =ROUND(375*'⚙️ Assumptions'!B25,0) -> 8438 | E30: =ROUND((375/'⚙️ Assumptions'!B8)*'🎪 Live-ops Calendar'!J13,0) -> 13777 | F30: =ROUND((375/'⚙️ Assumptions'!B8)*'⚙️ Assumptions'!B38,0) -> 8625 | G30: =C30+D30+E30-F30 -> 24840
A31: 400 | B31: =ROUND(400/'⚙️ Assumptions'!B8,1) -> 100 | C31: =A31*'⚙️ Assumptions'!$B$14*'⚙️ Assumptions'!$B$11 -> 12000 | D31: =ROUND(400*'⚙️ Assumptions'!B25,0) -> 9000 | E31: =ROUND((400/'⚙️ Assumptions'!B8)*'🎪 Live-ops Calendar'!J13,0) -> 14695 | F31: =ROUND((400/'⚙️ Assumptions'!B8)*'⚙️ Assumptions'!B38,0) -> 9200 | G31: =C31+D31+E31-F31 -> 26495
A32: 425 | B32: =ROUND(425/'⚙️ Assumptions'!B8,1) -> 106.3 | C32: =A32*'⚙️ Assumptions'!$B$14*'⚙️ Assumptions'!$B$11 -> 12750 | D32: =ROUND(425*'⚙️ Assumptions'!B25,0) -> 9563 | E32: =ROUND((425/'⚙️ Assumptions'!B8)*'🎪 Live-ops Calendar'!J13,0) -> 15613 | F32: =ROUND((425/'⚙️ Assumptions'!B8)*'⚙️ Assumptions'!B38,0) -> 9775 | G32: =C32+D32+E32-F32 -> 28151
A33: 450 | B33: =ROUND(450/'⚙️ Assumptions'!B8,1) -> 112.5 | C33: =A33*'⚙️ Assumptions'!$B$14*'⚙️ Assumptions'!$B$11 -> 13500 | D33: =ROUND(450*'⚙️ Assumptions'!B25,0) -> 10125 | E33: =ROUND((450/'⚙️ Assumptions'!B8)*'🎪 Live-ops Calendar'!J13,0) -> 16532 | F33: =ROUND((450/'⚙️ Assumptions'!B8)*'⚙️ Assumptions'!B38,0) -> 10350 | G33: =C33+D33+E33-F33 -> 29807
A34: 475 | B34: =ROUND(475/'⚙️ Assumptions'!B8,1) -> 118.8 | C34: =A34*'⚙️ Assumptions'!$B$14*'⚙️ Assumptions'!$B$11 -> 14250 | D34: =ROUND(475*'⚙️ Assumptions'!B25,0) -> 10688 | E34: =ROUND((475/'⚙️ Assumptions'!B8)*'🎪 Live-ops Calendar'!J13,0) -> 17450 | F34: =ROUND((475/'⚙️ Assumptions'!B8)*'⚙️ Assumptions'!B38,0) -> 10925 | G34: =C34+D34+E34-F34 -> 31463
A35: 500 | B35: =ROUND(500/'⚙️ Assumptions'!B8,1) -> 125 | C35: =A35*'⚙️ Assumptions'!$B$14*'⚙️ Assumptions'!$B$11 -> 15000 | D35: =ROUND(500*'⚙️ Assumptions'!B25,0) -> 11250 | E35: =ROUND((500/'⚙️ Assumptions'!B8)*'🎪 Live-ops Calendar'!J13,0) -> 18369 | F35: =ROUND((500/'⚙️ Assumptions'!B8)*'⚙️ Assumptions'!B38,0) -> 11500 | G35: =C35+D35+E35-F35 -> 33119

Sheet 💰 Daily Gold Flow
A1: Daily coin Flow Summary
A3: 📥 DAILY coin INFLOWS
A4: Source | B4: Basis | C4: Daily coin (Avg) | D4: % of Gross
A5: Level clears (base) | B5: Daily clears × coin per clear (B14) | C5: ='⚙️ Assumptions'!B27 -> 120 | D5: =IFERROR(C5/C8,0) -> 0.33618154
A6: Rewarded video bonus | B6: Daily clears × base coin × multiplier × watch rate | C6: ='⚙️ Assumptions'!B26 -> 90 | D6: =IFERROR(C6/C8,0) -> 0.25213615
A7: Live-ops (daily avg) | B7: From 🎪 Live-ops G13 — win-rate weighted avg across all events | C7: ='🎪 Live-ops Calendar'!J13 -> 146.95 | D7: =IFERROR(C7/C8,0) -> 0.41168231
A8: GROSS DAILY INCOME | C8: =SUM(C5:C7) -> 356.95
A10: 📤 DAILY coin SINKS
A11: Sink | B11: Basis | C11: Daily coin Lost | D11: % of Gross
A12: Revive/Boosters purchases | B12: Failed levels × trigger % × purchase rate × boosters/revive cost | C12: ='⚙️ Assumptions'!B38 -> 92 | D12: =IFERROR(C12/C8,0) -> 0.25773918
A13: TOTAL DAILY SINKS | C13: =C12 -> 92
A15: ⚖️ NET ECONOMY
A16: Net daily coin | C16: =C8-C13 -> 264.95
A17: Net weekly coin | C17: =C16*7 -> 1854.65
A18: Net monthly coin | C18: =C16*30 -> 7948.5
A19: Video boost % of gross | C19: =IFERROR(C6/C8,0) -> 0.25213615
A20: Live-ops % of gross | C20: =IFERROR(C7/C8,0) -> 0.41168231
A21: Board Full drain % | C21: =IFERROR(C13/C8,0) -> 0.25773918

Sheet 🎪 Live-ops Calendar
A1: Yarn Fever – Live-ops Event Economy (Win-Rate Model)
A2: 🔵 Blue = your inputs | Black = calculated | Avg Gold per Event = Max Reward × Win Rate
A3: Win Rate = % of participating players who earn the full/max reward for that event. Adjust per your analytics.
A4: Event | B4: Cadence (days) | C4: Max Reward (coin equivalent) | D4: Max Reward (coin only) | E4: Est. Win Rate | F4: Avg Coin Equi / Event | G4: Avg Coin Only / Event | H4: Monthly Occurrences | I4: Monthly Resource Impact | J4: Monthly Coin Impact | K4: Win Rate Rationale
A5: Live-ops Event 1 (Key Collection) | B5: 4 | C5: 5030 | D5: 1400 | E5: 0.5 | F5: =IF(ISNUMBER(C5),C5*E5,0) -> 2515 | G5: =IF(ISNUMBER(D5),D5*E5,0) -> 700 | H5: 4 | I5: =IF(ISNUMBER(B5)*ISNUMBER(C5),F5*H5,0) -> 10060 | J5: =IF(ISNUMBER(B5)*ISNUMBER(D5),G5*H5,0) -> 2800 | K5: Solo 25-stage collection event. Gold awarded at multiple milestone stages = max reward total. Low barrier, ~60% completion.
A6: Live-ops Event 2 (Master Pass) | B6: 30 | C6: 8280 | D6: 480 | E6: 0.6 | F6: =IF(ISNUMBER(C6),C6*E6,0) -> 4968 | G6: =IF(ISNUMBER(D6),D6*E6,0) -> 288 | H6: =IF(ISNUMBER(B6),ROUND(30/B6,1),"—") -> 1 | I6: =IF(ISNUMBER(B6)*ISNUMBER(C6),F6*H6,0) -> 4968 | J6: =IF(ISNUMBER(B6)*ISNUMBER(D6),G6*H6,0) -> 288 | K6: 30-day pass. Has both coins rewards and boosters
A7: Live-ops Event 3 (Win Streak) | B7: 3 | C7: 3000 | D7: 420 | E7: 0.6 | F7: =IF(ISNUMBER(C7),C7*E7,0) -> 1800 | G7: =IF(ISNUMBER(D7),D7*E7,0) -> 252 | H7: 4 | I7: =IF(ISNUMBER(B7)*ISNUMBER(C7),F7*H7,0) -> 7200 | J7: =IF(ISNUMBER(B7)*ISNUMBER(D7),G7*H7,0) -> 1008 | K7: Solo stage-based event, 9 stages. Rewards awarded at milestone stages. ~55% of active players complete all stages.
A8: Live-ops Event 4 (Card Album) | B8: 30 | C8: 12850 | D8: 6250 | E8: 0.05 | F8: =IF(ISNUMBER(C8),C8*E8,0) -> 642.5 | G8: =IF(ISNUMBER(D8),D8*E8,0) -> 312.5 | H8: =IF(ISNUMBER(B8),ROUND(30/B8,1),"—") -> 1 | I8: =IF(ISNUMBER(B8)*ISNUMBER(C8),F8*H8,0) -> 642.5 | J8: =IF(ISNUMBER(B8)*ISNUMBER(D8),G8*H8,0) -> 312.5 | K8: Card Album collection. Completing each set provides different rewards.
A9: Live-ops Event 5 (Stamp Card) | F9: =IF(ISNUMBER(C9),C9*E9,0) -> 0 | G9: =IF(ISNUMBER(D9),D9*E9,0) -> 0 | H9: =IF(ISNUMBER(B9),ROUND(30/B9,1),"—") -> — | I9: =IF(ISNUMBER(B9)*ISNUMBER(C9),F9*H9,0) -> 0 | J9: =IF(ISNUMBER(B9)*ISNUMBER(D9),G9*H9,0) -> 0
A10: Live-ops Event 6 | F10: =IF(ISNUMBER(C10),C10*E10,0) -> 0 | G10: =IF(ISNUMBER(D10),D10*E10,0) -> 0 | H10: =IF(ISNUMBER(B10),ROUND(30/B10,1),"—") -> — | I10: =IF(ISNUMBER(B10)*ISNUMBER(C10),F10*H10,0) -> 0 | J10: =IF(ISNUMBER(B10)*ISNUMBER(D10),G10*H10,0) -> 0
A11: Live-ops Event 7 | F11: =IF(ISNUMBER(C11),C11*E11,0) -> 0 | G11: =IF(ISNUMBER(D11),D11*E11,0) -> 0 | H11: =IF(ISNUMBER(B11),ROUND(30/B11,1),"—") -> — | I11: =IF(ISNUMBER(B11)*ISNUMBER(C11),F11*H11,0) -> 0 | J11: =IF(ISNUMBER(B11)*ISNUMBER(D11),G11*H11,0) -> 0
A12: TOTAL MONTHLY LIVE-OPS GOLD | I12: =SUM(I5:I11) -> 22870.5 | J12: =SUM(J5:J11) -> 4408.5
A13: Daily avg gold from live-ops | I13: =I12/30 -> 762.35 | J13: =J12/30 -> 146.95
A15: 💡 Daily avg (G13) is automatically pulled into '💰 Daily Gold Flow' as the live-ops income line.
